<?xml version="1.0"?>
<sdf version="1.6">
    <model name="demo_joint_types">
        <link name="heavy_base">
            <!-- position the base such that the bottom touches the floor -->
            <pose>0 0 0.05 0 0 0</pose>
            <inertial>
                <mass>100</mass>                <!-- kg -->
                <inertia>
                    <!-- (mass / 12) * (y*y + z*z) -->
                    <ixx>8.4167</ixx>
                    <ixy>0</ixy>
                    <ixz>0</ixz>
                    <!-- (mass / 12) * (x*x + z*z) -->
                    <iyy>40.417</iyy>
                    <iyz>0</iyz>
                    <!-- (mass / 12) * (y*y + x*x) -->
                    <izz>48.667</izz>
                </inertia>
            </inertial>
            <!-- Same geometry as visual -->
            <collision name="heavy_base_collision">
                <geometry>
                    <box>
                        <size>2.2 1 0.1</size>
                    </box>
                </geometry>
            </collision>
            <!-- Same geometry as collision -->
            <visual name="heavy_base_visual">
                <geometry>
                    <box>
                        <size>2.2 1 0.1</size>
                    </box>
                </geometry>
                <material>
                    <script>
                        <uri>file://media/materials/scripts/gazebo.material</uri>
                        <name>Gazebo/Black</name>
                    </script>
                </material>
            </visual>
        </link>

        <link name="fixed_base">
            <!-- Put the bottom of base on top of the heavy base -->
            <pose >0 0 0.35 0 0 0</pose>
            <inertial>
                <inertia>
                    <!-- (mass / 12) * (y*y + z*z) -->
                    <ixx>0.021667</ixx>
                    <ixy>0</ixy>
                    <ixz>0</ixz>
                    <!-- (mass / 12) * (x*x + z*z) -->
                    <iyy>0.021667</iyy>
                    <iyz>0</iyz>
                    <!-- (mass / 12) * (y*y + x*x) -->
                    <izz>0.0016667</izz>
                </inertia>
            </inertial>
            <!-- Same geometry as visual -->
            <collision name="fixed_base_collision">
                <geometry>
                    <box>
                        <size>0.1 0.1 0.5</size>
                    </box>
                </geometry>
            </collision>
            <!-- Same geometry as collision -->
            <visual name="fixed_base_visual">
                <geometry>
                    <box>
                        <size>0.1 0.1 0.5</size>
                    </box>
                </geometry>
                <material>
                </material>
            </visual>
        </link>
        <link name="fixed_arm">
            <!-- Put the arm near the top of the base -->
            <pose >0.1 0.07 0.55 0 0 0</pose>
            <inertial>
                <inertia>
                    <!-- (mass / 12) * (y*y + z*z) -->
                    <ixx>0.0060417</ixx>
                    <ixy>0</ixy>
                    <ixz>0</ixz>
                    <!-- (mass / 12) * (x*x + z*z) -->
                    <iyy>0.0016667</iyy>
                    <iyz>0</iyz>
                    <!-- (mass / 12) * (y*y + x*x) -->
                    <izz>0.0060417</izz>
                </inertia>
            </inertial>
            <!-- Same geometry as visual -->
            <collision name="fixed_arm_collision">
                <geometry>
                    <box>
                        <size>0.1 0.25 0.1</size>
                    </box>
                </geometry>
            </collision>
            <!-- Same geometry as collision -->
            <visual name="fixed_arm_visual">
                <geometry>
                    <box>
                        <size>0.1 0.25 0.1</size>
                    </box>
                </geometry>
                <material>
                    <script>
                        <uri>file://media/materials/scripts/gazebo.material</uri>
                        <name>Gazebo/Red</name>
                    </script>
                </material>
            </visual>
        </link>

        <joint name="fixed_demo" type="revolute">
            <pose>0 -0.025 0 0 0 0</pose>
            <parent>fixed_base</parent>
            <child>fixed_arm</child>
            <axis>
                <xyz>1 0 0</xyz>
            </axis>
        </joint>

        <joint name="fixed_base_to_heavy_base" type="fixed">
            <parent>heavy_base</parent>
            <child>fixed_base</child>
        </joint>
    </model>
</sdf>